File: PhD/giga_dash/EVERYTHING_FeSb2-VT73_FeSb2-VT64-GeGa3-VLS2_1p8K.dat
[Header]
TITLE, default name
FILEOPENTIME,1608641281.00,12/22/2020,12:48 PM
BYAPP, Resistivity, 2.0, 1.0
INFO, , Sample1 Name
INFO, 1, Sample1 Cross Section
INFO, 1, Sample1 Length
INFO, Ohm-m, Sample1 Units
INFO, , Sample2 Name
INFO, 1, Sample2 Cross Section
INFO, 1, Sample2 Length
INFO, Ohm-m, Sample2 Units
INFO, , Sample3 Name
INFO, 1, Sample3 Cross Section
INFO, 1, Sample3 Length
INFO, Ohm-m, Sample3 Units
INFO, , Sample4 Name
INFO, 1, Sample4 Cross Section
INFO, 1, Sample4 Length
INFO, Ohm-m, Sample4 Units
FIELDGROUP, Resistivity,2,3,4,5,6,7,8,9,10,11,12,13,14,15,16,17,18,19,20,21,22,23,24,25,26,27,28,29,30,31,32,33,34,35,36,37,38,39,40,41
STARTUPGROUP, Resistivity
STARTUPAXIS, X, 2, LINEAR, AUTO
STARTUPAXIS, Y1, 7, LINEAR, AUTO
STARTUPAXIS, Y2, 9, LINEAR, AUTO
STARTUPAXIS, Y3, 11, LINEAR, AUTO
PLOT_APPEARANCE, ALL, HORZ_GRID_ON, VERT_GRID_ON, MARKERS_AND_LINES, ALL_LINES
DATATYPE, TIME, 2
DATATYPE, COMMENT, 1
[Data]
Comment,Time Stamp (sec),Status (code),Temperature (K),Magnetic Field (Oe),Sample Position (degrees),Bridge 1 Resistivity (Ohm-m),Bridge 1 Excitation (uA),Bridge 2 Resistivity (Ohm-m),Bridge 2 Excitation (uA),Bridge 3 Resistivity (Ohm-m),Bridge 3 Excitation (uA),Bridge 4 Resistivity (Ohm-m),Bridge 4 Excitation (uA),Bridge 1 Std. Dev. (Ohm-m),Bridge 2 Std. Dev. (Ohm-m),Bridge 3 Std. Dev. (Ohm-m),Bridge 4 Std. Dev. (Ohm-m),Number of Readings,Bridge 1 Resistance (Ohms),Bridge 2 Resistance (Ohms),Bridge 3 Resistance (Ohms),Bridge 4 Resistance (Ohms)
,30908968.938,,1.79981153011322,2447.23227050781,5.87874675199031e+022,4.23223166015625,0.999890267848969,3.72435293945313,0.999890267848969,1486.53172,0.999890267848969,,,0.000786768915880707,0.00120117671692944,0.825008013026651,,25,4232.23166015625,3724.35293945313,1486531.72,
,30909442.313,,1.80000264644623,49816.03296875,5.87874675199031e+022,4.30050474609375,0.999890267848969,3.80386784179688,0.999890267848969,1476.482535,0.999890267848969,,,0.00117767253998002,0.00136112965568869,0.0901368248629953,,25,4300.50474609375,3803.86784179687,1476482.535,
,30909916.672,,1.79999811649323,97379.01,5.87874675199031e+022,4.361534609375,0.999890267848969,3.87098403320313,0.999890267848969,1474.07372,0.999890267848969,,,0.000287039922813465,0.00032890288020542,0.118374271053469,,25,4361.534609375,3870.98403320312,1474073.72,
,30910389.094,,1.80001146793365,140000.25,5.87874675199031e+022,4.36019453125,0.999890267848969,3.8535076171875,0.999890267848969,1472.184515,0.999890267848969,,,0.000277665338046112,0.000204198149275804,0.0949936767876764,,25,4360.19453125,3853.5076171875,1472184.515,
,30910861.797,,1.80000034809113,140000.44875,5.87874675199031e+022,4.35925310546875,0.999890267848969,3.85253961914063,0.999890267848969,1472.15212,0.999890267848969,,,0.000217714277303944,0.00022901425498531,0.168212443546316,,25,4359.25310546875,3852.53961914062,1472152.12,
,30911335.422,,1.79999770641327,140000.344375,5.87874675199031e+022,4.35917533203125,0.999890267848969,3.85225611328125,0.999890267848969,1472.19168,0.999890267848969,,,0.000198836574543082,0.000303618639066921,0.0734206346411941,,25,4359.17533203125,3852.25611328125,1472191.68,
,30911812.422,,1.80002092838287,101546.794375,5.87874675199031e+022,4.3627848828125,0.999890267848969,3.87130940429687,0.999890267848969,1473.85316,0.999890267848969,,,0.000296113823627884,0.000314726699953271,0.0850376955324628,,25,4362.7848828125,3871.30940429688,1473853.16,
,30912283.985,,1.80001303195953,54765.348125,5.87874675199031e+022,4.31002435546875,0.999890267848969,3.81669099609375,0.999890267848969,1476.67376,0.999890267848969,,,0.00109564225429639,0.00110207069396645,0.124029223239541,,25,4310.02435546875,3816.69099609375,1476673.76,
,30912757.969,,1.80008123397827,7541.709375,5.87874675199031e+022,4.22981091796875,0.999890267848969,3.72126720703125,0.999890267848969,1482.936155,0.999890267848969,,,0.000307044977994939,0.000713850433929215,0.256225218824875,,25,4229.81091796875,3721.26720703125,1482936.155,
,30913230.313,,1.79999315738678,-39708.9646875,5.87874675199031e+022,4.27916115234375,0.999890267848969,3.77822551757812,0.999890267848969,1477.610385,0.999890267848969,,,0.00124901789408052,0.00142100903682954,0.132673848580455,,25,4279.16115234375,3778.22551757813,1477610.385,
,30913703.094,,1.80000425815582,-86995.2996875,5.87874675199031e+022,4.354534296875,0.999890267848969,3.86471491210937,0.999890267848969,1474.882095,0.999890267848969,,,0.000457981266364232,0.000341863293570214,0.108577245720523,,25,4354.534296875,3864.71491210937,1474882.095,
,30914176.875,,1.80000242710114,-134368.331875,5.87874675199031e+022,4.36328265625,0.999890267848969,3.85711805664063,0.999890267848969,1472.26146,0.999890267848969,,,0.00029696626392719,0.000523823220283778,0.105455912144255,,25,4363.28265625,3857.11805664063,1472261.46,
,30914649.813,,1.80000525474548,-140000.250625,5.87874675199031e+022,4.3606253125,0.999890267848969,3.85145181640625,0.999890267848969,1472.189255,0.999890267848969,,,0.000219388415241027,0.000307774653653778,0.0905998923815592,,25,4360.6253125,3851.45181640625,1472189.255,
,30915122.438,,1.80000749588013,-140000.416875,5.87874675199031e+022,4.36044681640625,0.999890267848969,3.850835390625,0.999890267848969,1472.49769,0.999890267848969,,,0.000194015984506728,0.000235539404089082,0.0979712745730602,,25,4360.44681640625,3850.835390625,1472497.69,
,30915594.469,,1.80000406265259,-140000.30875,5.87874675199031e+022,4.36018865234375,0.999890267848969,3.85068131835938,0.999890267848969,1472.302025,0.999890267848969,,,0.000168024520999763,0.000276609179173655,0.118855142161718,,25,4360.18865234375,3850.68131835937,1472302.025,
,30916066.297,,1.80000857830048,-140000.2175,5.87874675199031e+022,4.36027564453125,0.999890267848969,3.8506677734375,0.999890267848969,1472.34138,0.999890267848969,,,0.000215851544950827,0.000314475492577572,0.132475773214806,,25,4360.27564453125,3850.6677734375,1472341.38,
,30916541.235,,1.80001291275024,-123750.2390625,5.87874675199031e+022,4.3654953125,0.999890267848969,3.86411544921875,0.999890267848969,1472.844985,0.999890267848969,,,0.000218292472504007,0.000317769897839641,0.106961571068741,,25,4365.4953125,3864.11544921875,1472844.985,
,30917013.782,,1.80001414299011,-76890.274375,5.87874675199031e+022,4.3446553515625,0.999890267848969,3.85437782226563,0.999890267848969,1475.46981,0.999890267848969,,,0.00056211221995605,0.000786679088073061,0.106528223627532,,25,4344.6553515625,3854.37782226563,1475469.81,
,30917486.657,,1.80002834320068,-29713.47734375,5.87874675199031e+022,4.2586740234375,0.999890267848969,3.75294624023437,0.999890267848969,1478.94224,0.999890267848969,,,0.00114259668053374,0.00143526450806205,0.136717922344427,,25,4258.6740234375,3752.94624023438,1478942.24,
,30917959,,1.79999540328979,-0.108380591273308,5.87874675199031e+022,4.23462765625,0.999890267848969,3.72825493164062,0.999890267848969,1488.70814,0.999890267848969,,,0.000460908331159984,0.000519976574782616,0.15164681877692,,25,4234.62765625,3728.25493164062,1488708.14,
,30918432.625,,1.80000641345978,-0.236400620341301,5.87874675199031e+022,4.234485234375,0.999890267848969,3.72781615234375,0.999890267848969,1488.826495,0.999890267848969,,,0.000459057000222418,0.000573230730731868,0.141310112370976,,25,4234.485234375,3727.81615234375,1488826.495,
,30918975.313,,1.79994695186615,14281.655234375,5.87874675199031e+022,4.17645146484375,9.99890232086182,3.6191512109375,9.99890232086182,1489.599875,9.99890232086182,,,0.00127313242653707,0.00131438594892037,2.15791864375777e-005,,25,4176.45146484375,3619.1512109375,1489599.875,
,30919955.313,,1.79996037483215,112462.0403125,5.87874675199031e+022,4.30385876953125,9.99890232086182,3.76072330078125,9.99890232086182,1489.599875,9.99890232086182,,,0.000168581472307358,0.000241452272994303,2.15791864375777e-005,,25,4303.85876953125,3760.72330078125,1489599.875,
,30920927.313,,1.80002807617188,140000.36625,5.87874675199031e+022,4.29798828125,9.99890232086182,3.74320795898437,9.99890232086182,1489.599875,9.99890232086182,,,0.00020959957020893,0.000244059910373708,2.15791864375777e-005,,25,4297.98828125,3743.20795898438,1489599.875,
,30921906.25,,1.79993022441864,140000.2525,5.87874675199031e+022,4.2975578125,9.99890232086182,3.74260708007813,9.99890232086182,1489.599875,9.99890232086182,,,0.000173719278690471,0.000232255152441133,2.15791864375777e-005,,25,4297.5578125,3742.60708007812,1489599.875,
,30922885.86,,1.79999406337738,140000.183125,5.87874675199031e+022,4.2972459375,9.99890232086182,3.74227533203125,9.99890232086182,1489.599875,9.99890232086182,,,0.000176577037388409,0.000228753533575224,2.15791864375777e-005,,25,4297.2459375,3742.27533203125,1489599.875,
,30923871.469,,1.79998391151428,140000.204375,5.87874675199031e+022,4.2971121484375,9.99890232086182,3.74206651367188,9.99890232086182,1489.599875,9.99890232086182,,,0.000164972596171818,0.000194610812755638,2.15791864375777e-005,,25,4297.1121484375,3742.06651367187,1489599.875,
,30924856.469,,1.80004153728485,50212.3175,5.87874675199031e+022,4.24326630859375,9.99890232086182,3.6977457421875,9.99890232086182,1489.599875,9.99890232086182,,,0.00244801027437861,0.00285425879119629,2.15791864375777e-005,,25,4243.26630859375,3697.7457421875,1489599.875,
,30925819.797,,1.79998730659485,-46088.29953125,5.87874675199031e+022,4.23496423828125,9.99890232086182,3.68685890625,9.99890232086182,1489.599875,9.99890232086182,,,0.00267313967204389,0.0030273292360962,2.15791864375777e-005,,25,4234.96423828125,3686.85890625,1489599.875,
,30926788.516,,1.79998786449432,-140000.3875,5.87874675199031e+022,4.2999425,9.99890232086182,3.74307430664063,9.99890232086182,1489.599875,9.99890232086182,,,9.82721356609134e-005,0.000177656035804148,2.15791864375777e-005,,25,4299.9425,3743.07430664062,1489599.875,
,30927759.657,,1.80001877784729,-140000.1325,5.87874675199031e+022,4.2994746875,9.99890232086182,3.74209803710937,9.99890232086182,1489.599875,9.99890232086182,,,0.000199788349948672,0.000202563085809074,2.15791864375777e-005,,25,4299.4746875,3742.09803710938,1489599.875,
,30928731.469,,1.80001582145691,-140000.194375,5.87874675199031e+022,4.299257421875,9.99890232086182,3.74190924804688,9.99890232086182,1489.599875,9.99890232086182,,,0.000137252802461005,0.000167067071918333,2.15791864375777e-005,,25,4299.257421875,3741.90924804687,1489599.875,
,30929707.954,,1.8000010061264,-140000.301875,5.87874675199031e+022,4.29915037109375,9.99890232086182,3.74169727539062,9.99890232086182,1489.599875,9.99890232086182,,,0.000194684081021486,0.000261528116375177,2.15791864375777e-005,,25,4299.15037109375,3741.69727539062,1489599.875,
,30930667.25,,1.79998778343201,-140000.270625,5.87874675199031e+022,4.29917189453125,9.99890232086182,3.74154880859375,9.99890232086182,1489.599875,9.99890232086182,,,0.000203940530130679,0.000218490567570325,2.15791864375777e-005,,25,4299.17189453125,3741.54880859375,1489599.875,
,30931635.329,,1.80001208782196,-140000.373125,5.87874675199031e+022,4.29907466796875,9.99890232086182,3.7413716015625,9.99890232086182,1489.599875,9.99890232086182,,,0.00023513842746323,0.000265650629951221,2.15791864375777e-005,,25,4299.07466796875,3741.3716015625,1489599.875,
,30932603.079,,1.79998518466949,-140000.241875,5.87874675199031e+022,4.299007109375,9.99890232086182,3.74131568359375,9.99890232086182,1489.599875,9.99890232086182,,,0.000160353743412389,0.000250790227870308,2.15791864375777e-005,,25,4299.007109375,3741.31568359375,1489599.875,
,30933575.813,,1.80004450321198,-140000.17625,5.87874675199031e+022,4.2987801171875,9.99890232086182,3.7412646875,9.99890232086182,1489.599875,9.99890232086182,,,0.000277216903234474,0.000279623958092592,2.15791864375777e-005,,25,4298.7801171875,3741.2646875,1489599.875,
,30934555.969,,1.79996726512909,-96690.2609375,5.87874675199031e+022,4.3004169140625,9.99890232086182,3.75915090820313,9.99890232086182,1489.599875,9.99890232086182,,,0.000704512852159156,0.000514717261940338,2.15791864375777e-005,,25,4300.4169140625,3759.15090820312,1489599.875,
,30935530.735,,1.79939915657043,-331.839752063751,5.87874675199031e+022,4.17832287109375,9.99890232086182,3.62548375976562,9.99890232086182,1489.599875,9.99890232086182,,,0.00164908493745858,0.00234640374954959,2.15791864375777e-005,,25,4178.32287109375,3625.48375976563,1489599.875,
,30936500.235,,1.80002493858337,-0.257494829893112,5.87874675199031e+022,4.17746857421875,9.99890232086182,3.62441159179688,9.99890232086182,1489.599875,9.99890232086182,,,0.000142902157602517,0.000512941665536293,2.15791864375777e-005,,25,4177.46857421875,3624.41159179688,1489599.875,
,30937466.657,,1.80002377510071,-0.168026288449764,5.87874675199031e+022,4.177086328125,9.99890232086182,3.62420731445313,9.99890232086182,1489.599875,9.99890232086182,,,0.000207318115803714,0.000507092695670758,2.15791864375777e-005,,25,4177.086328125,3624.20731445313,1489599.875,
,30938441.297,,1.80000482559204,0.104016273990273,5.87874675199031e+022,4.17705080078125,9.99890232086182,3.62390396484375,9.99890232086182,1489.599875,9.99890232086182,,,0.000181075055515793,0.000498627469710349,2.15791864375777e-005,,25,4177.05080078125,3623.90396484375,1489599.875,
,30939419.641,,1.80000059604645,23927.535390625,5.87874675199031e+022,3.9516945703125,49.99951171875,3.22059236328125,49.99951171875,1489.599875,49.99951171875,,,0.00202765731144782,0.0019972923610669,2.15791864375777e-005,,25,3951.6945703125,3220.59236328125,1489599.875,
,30940401.079,,1.80008725643158,122358.96625,5.87874675199031e+022,4.05675830078125,49.99951171875,3.32405336914062,49.99951171875,1489.599875,49.99951171875,,,0.000509866573123603,0.00066334942277388,2.15791864375777e-005,,25,4056.75830078125,3324.05336914062,1489599.875,
,30941369.125,,1.7999661397934,140000.225,5.87874675199031e+022,4.05250663085937,49.99951171875,3.31467630859375,49.99951171875,1489.599875,49.99951171875,,,0.000424167533436095,0.00048141045473248,2.15791864375777e-005,,25,4052.50663085938,3314.67630859375,1489599.875,
,30942333.454,,1.80002996921539,140000.41,5.87874675199031e+022,4.052182890625,49.99951171875,3.314533203125,49.99951171875,1489.599875,49.99951171875,,,0.000429502658023133,0.000440380442219849,2.15791864375777e-005,,25,4052.182890625,3314.533203125,1489599.875,
,30943302.938,,1.80008130550385,140000.135625,5.87874675199031e+022,4.05205126953125,49.99951171875,3.31439661132813,49.99951171875,1489.599875,49.99951171875,,,0.000460524351723254,0.000435421068551251,2.15791864375777e-005,,25,4052.05126953125,3314.39661132812,1489599.875,
,30944262.063,,1.80002751350403,137376.713125,5.87874675199031e+022,4.0526453515625,49.99951171875,3.31601734375,49.99951171875,1489.599875,49.99951171875,,,0.000538366170870526,0.000867026530684802,2.15791864375777e-005,,25,4052.6453515625,3316.01734375,1489599.875,
,30945240.157,,1.79996882915497,40362.1415625,5.87874675199031e+022,3.9804303515625,49.99951171875,3.25064336914062,49.99951171875,1489.599875,49.99951171875,,,0.00231952168717451,0.00237782208074764,2.15791864375777e-005,,25,3980.4303515625,3250.64336914063,1489599.875,
,30946219.407,,1.80002292633057,-57498.5509375,5.87874675199031e+022,4.00971580078125,49.99951171875,3.280333359375,49.99951171875,1489.599875,49.99951171875,,,0.00203292598143842,0.00212104586928829,2.15791864375777e-005,,25,4009.71580078125,3280.333359375,1489599.875,
,30947194.282,,1.79992280006409,-140000.32875,5.87874675199031e+022,4.05396612304687,49.99951171875,3.31447474609375,49.99951171875,1489.599875,49.99951171875,,,0.000327917714600506,0.000330522744782218,2.15791864375777e-005,,25,4053.96612304688,3314.47474609375,1489599.875,
,30948167.047,,1.80012469768524,-140000.25375,5.87874675199031e+022,4.05372568359375,49.99951171875,3.31415815429687,49.99951171875,1489.599875,49.99951171875,,,0.000291620352490991,0.000307567157633582,2.15791864375777e-005,,25,4053.72568359375,3314.15815429688,1489599.875,
,30949137.782,,1.800194439888,-140000.335625,5.87874675199031e+022,4.05372860351563,49.99951171875,3.31404209960938,49.99951171875,1489.599875,49.99951171875,,,0.000465363347106655,0.000454059274020326,2.15791864375777e-005,,25,4053.72860351562,3314.04209960937,1489599.875,
,30950117.641,,1.79988744735718,-140000.22625,5.87874675199031e+022,4.05351630859375,49.99951171875,3.31403107421875,49.99951171875,1489.599875,49.99951171875,,,0.000307322218955635,0.000283946380726205,2.15791864375777e-005,,25,4053.51630859375,3314.03107421875,1489599.875,
,30951092.032,,1.80004313468933,-139999.998125,5.87874675199031e+022,4.05366772460938,49.99951171875,3.31395548828125,49.99951171875,1489.599875,49.99951171875,,,0.000502892967941945,0.000480566138430779,2.15791864375777e-005,,25,4053.66772460938,3313.95548828125,1489599.875,
,30952061.922,,1.8001185131073,-139999.89625,5.87874675199031e+022,4.05391462890625,49.99951171875,3.31389758789062,49.99951171875,1489.599875,49.99951171875,,,0.000585252291798816,0.000453467718788785,2.15791864375777e-005,,25,4053.91462890625,3313.89758789062,1489599.875,
,30953036.438,,1.7998991394043,-140000.061875,5.87874675199031e+022,4.05384826171875,49.99951171875,3.31383865234375,49.99951171875,1489.599875,49.99951171875,,,0.000618441384886585,0.00043820792053818,2.15791864375777e-005,,25,4053.84826171875,3313.83865234375,1489599.875,
,30954018.032,,1.79993293762207,-140000.025625,5.87874675199031e+022,4.05366809570312,49.99951171875,3.31377874023438,49.99951171875,1489.599875,49.99951171875,,,0.000459275115209192,0.000353144671109799,2.15791864375777e-005,,25,4053.66809570312,3313.77874023438,1489599.875,
,30954986.704,,1.80002724647522,-86119.3146875,5.87874675199031e+022,4.04481294921875,49.99951171875,3.31592810546875,49.99951171875,1489.599875,49.99951171875,,,0.00108056363102784,0.00120608318729898,2.15791864375777e-005,,25,4044.81294921875,3315.92810546875,1489599.875,
,30955951.907,,1.79995621681213,-0.0778303576260805,5.87874675199031e+022,3.93790669921875,49.99951171875,3.21004326171875,49.99951171875,1489.599875,49.99951171875,,,0.000405286293345151,0.000219875794585513,2.15791864375777e-005,,25,3937.90669921875,3210.04326171875,1489599.875,
,30956909.282,,1.80005956172943,-0.151296399533749,5.87874675199031e+022,3.93774833984375,49.99951171875,3.20997544921875,49.99951171875,1489.599875,49.99951171875,,,0.000257914649494826,0.000959702298354039,2.15791864375777e-005,,25,3937.74833984375,3209.97544921875,1489599.875,
,30957878.391,,1.79996126174927,-0.106198432594538,5.87874675199031e+022,3.9375400390625,49.99951171875,3.20982016601562,49.99951171875,1489.599875,49.99951171875,,,0.000267984173205584,0.000960923331770937,2.15791864375777e-005,,25,3937.5400390625,3209.82016601563,1489599.875,
,30958846.954,,1.80006255626678,-0.156388104707003,5.87874675199031e+022,3.93752614257813,49.99951171875,3.20966154296875,49.99951171875,1489.599875,49.99951171875,,,0.000302453044234074,0.000877691863447247,2.15791864375777e-005,,25,3937.52614257813,3209.66154296875,1489599.875,
,30959828.438,,1.79998466968536,34289.435703125,5.87874675199031e+022,3.69425759765625,99.9890289306641,2.86170615234375,99.9890289306641,1489.599875,99.9890289306641,,,0.00215156552170688,0.00181570652986972,2.15791864375777e-005,,25,3694.25759765625,2861.70615234375,1489599.875,
,30960797.5,,1.79991362094879,131365.81625,5.87874675199031e+022,3.7813186328125,99.9890289306641,2.9375842578125,99.9890289306641,1489.599875,99.9890289306641,,,0.000385559720326219,0.000425819607906012,2.15791864375777e-005,,25,3781.3186328125,2937.5842578125,1489599.875,
,30961764.704,,1.80000236034393,140000.26875,5.87874675199031e+022,3.77957201171875,99.9890289306641,2.93400577148438,99.9890289306641,1489.599875,99.9890289306641,,,0.000310478989802406,0.000281113561885644,2.15791864375777e-005,,25,3779.57201171875,2934.00577148438,1489599.875,
,30962735.329,,1.79994492530823,140000.221875,5.87874675199031e+022,3.77940017578125,99.9890289306641,2.9338112890625,99.9890289306641,1489.599875,99.9890289306641,,,0.000317711283316237,0.000263605498847023,2.15791864375777e-005,,25,3779.40017578125,2933.8112890625,1489599.875,
,30963707.938,,1.79995223522186,140000.34,5.87874675199031e+022,3.7795102734375,99.9890289306641,2.93403810546875,99.9890289306641,1489.599875,99.9890289306641,,,0.000558682018912664,0.000554483404004222,2.15791864375777e-005,,25,3779.5102734375,2934.03810546875,1489599.875,
,30964675.016,,1.80033289432526,127021.17125,5.87874675199031e+022,3.78143196289063,99.9890289306641,2.93829732421875,99.9890289306641,1489.599875,99.9890289306641,,,0.000537618619488747,0.000635400854606771,2.15791864375777e-005,,25,3781.43196289063,2938.29732421875,1489599.875,
,30965640.86,,1.80005722999573,31296.201875,5.87874675199031e+022,3.69011201171875,99.9890289306641,2.85788772460938,99.9890289306641,1489.599875,99.9890289306641,,,0.00228065124567563,0.00167131226950776,2.15791864375777e-005,,25,3690.11201171875,2857.88772460937,1489599.875,
,30966603.454,,1.79989794254303,-64813.1053125,5.87874675199031e+022,3.74159116210938,99.9890289306641,2.9059810546875,99.9890289306641,1489.599875,99.9890289306641,,,0.00167420026818272,0.00156132016689423,2.15791864375777e-005,,25,3741.59116210938,2905.9810546875,1489599.875,
,30967570.547,,1.80008548259735,-140000.31125,5.87874675199031e+022,3.78058318359375,99.9890289306641,2.9347876953125,99.9890289306641,1489.599875,99.9890289306641,,,0.000519309987105977,0.000456836143837436,2.15791864375777e-005,,25,3780.58318359375,2934.7876953125,1489599.875,
,30968545.094,,1.80011730670929,-140000.355625,5.87874675199031e+022,3.78032297851563,99.9890289306641,2.93469751953125,99.9890289306641,1489.599875,99.9890289306641,,,0.000558699005394818,0.000504412850845689,2.15791864375777e-005,,25,3780.32297851563,2934.69751953125,1489599.875,
,30969503.922,,1.80008765697479,-140000.246875,5.87874675199031e+022,3.780267578125,99.9890289306641,2.93436157226563,99.9890289306641,1489.599875,99.9890289306641,,,0.000544408429297084,0.000443468553211879,2.15791864375777e-005,,25,3780.267578125,2934.36157226563,1489599.875,
,30970476.532,,1.8001448392868,-140000.26875,5.87874675199031e+022,3.78018139648437,99.9890289306641,2.93434411132812,99.9890289306641,1489.599875,99.9890289306641,,,0.000551544558553354,0.000527549237342658,2.15791864375777e-005,,25,3780.18139648438,2934.34411132813,1489599.875,
,30971439.532,,1.79981370449066,-140000.270625,5.87874675199031e+022,3.7801626171875,99.9890289306641,2.93437379882813,99.9890289306641,1489.599875,99.9890289306641,,,0.000598938015228484,0.000515118622147606,2.15791864375777e-005,,25,3780.1626171875,2934.37379882813,1489599.875,
,30972406.36,,1.79987753868103,-140000.204375,5.87874675199031e+022,3.78002857421875,99.9890289306641,2.93415022460938,99.9890289306641,1489.599875,99.9890289306641,,,0.000298396815147486,0.0003131895531265,2.15791864375777e-005,,25,3780.02857421875,2934.15022460938,1489599.875,
,30973381.235,,1.79996789932251,-140000.185,5.87874675199031e+022,3.78019563476562,99.9890289306641,2.93428139648438,99.9890289306641,1489.599875,99.9890289306641,,,0.000438884380010966,0.000497409362001486,2.15791864375777e-005,,25,3780.19563476563,2934.28139648437,1489599.875,
,30974345.704,,1.79982716083527,-140000.205625,5.87874675199031e+022,3.78005529296875,99.9890289306641,2.9342668359375,99.9890289306641,1489.599875,99.9890289306641,,,0.000275953058829992,0.000341074581813094,2.15791864375777e-005,,25,3780.05529296875,2934.2668359375,1489599.875,
,30975313.782,,1.79971625328064,-77155.2471875,5.87874675199031e+022,3.756638203125,99.9890289306641,2.9200767578125,99.9890289306641,1489.599875,99.9890289306641,,,0.00122271006878656,0.00112353449625426,2.15791864375777e-005,,25,3756.638203125,2920.0767578125,1489599.875,
,30976282.516,,1.79996557235718,-0.0378240998089314,5.87874675199031e+022,3.64718166992188,99.9890289306641,2.83225633789063,99.9890289306641,1489.599875,99.9890289306641,,,0.000441639852254463,0.000964324286365068,2.15791864375777e-005,,25,3647.18166992187,2832.25633789063,1489599.875,
,30977249.454,,1.79997099399567,-0.267678244709969,5.87874675199031e+022,3.64687444335937,99.9890289306641,2.83216493164063,99.9890289306641,1489.599875,99.9890289306641,,,0.000394714693917018,0.000910076135736141,2.15791864375777e-005,,25,3646.87444335938,2832.16493164063,1489599.875,
,30978219.079,,1.80016761779785,-0.352782467603683,5.87874675199031e+022,3.6467658984375,99.9890289306641,2.8317967578125,99.9890289306641,1489.599875,99.9890289306641,,,0.000319131489543797,0.00034235323117398,2.15791864375777e-005,,25,3646.7658984375,2831.7967578125,1489599.875,
,30979201.797,,1.80007021903992,-0.323687008023262,5.87874675199031e+022,3.64686899414062,99.9890289306641,2.8318640625,99.9890289306641,1489.599875,99.9890289306641,,,0.00030530043660065,0.000903555472225681,2.15791864375777e-005,,25,3646.86899414063,2831.8640625,1489599.875,
,30980189.735,,1.80001817703247,45206.15140625,5.87874675199031e+022,3.26799338867188,199.99055480957,2.390139453125,199.99055480957,1489.599875,199.99055480957,,,0.00271468543562796,0.00151624255281474,2.15791864375777e-005,,25,3267.99338867188,2390.139453125,1489599.875,
,30981154.016,,1.79980884552002,139987.1275,5.87874675199031e+022,3.352293125,199.99055480957,2.44559971679687,199.99055480957,1489.599875,199.99055480957,,,0.000310554199191474,0.00032677375927108,2.15791864375777e-005,,25,3352.293125,2445.59971679687,1489599.875,
,30982120.547,,1.79995820045471,140000.421875,5.87874675199031e+022,3.35206549804687,199.99055480957,2.445551171875,199.99055480957,1489.599875,199.99055480957,,,0.000230162681714864,0.000246309227940096,2.15791864375777e-005,,25,3352.06549804687,2445.551171875,1489599.875,
,30983081.11,,1.80014485359192,140000.004375,5.87874675199031e+022,3.35220065429688,199.99055480957,2.44544525390625,199.99055480957,1489.599875,199.99055480957,,,0.00038518280866782,0.000452792408878487,2.15791864375777e-005,,25,3352.20065429688,2445.44525390625,1489599.875,
,30984053.36,,1.8001514673233,140000.066875,5.87874675199031e+022,3.35211138671875,199.99055480957,2.44544670898437,199.99055480957,1489.599875,199.99055480957,,,0.000266163114693509,0.00040234914493071,2.15791864375777e-005,,25,3352.11138671875,2445.44670898438,1489599.875,
,30985033.735,,1.80007222652435,117124.3415625,5.87874675199031e+022,3.348014453125,199.99055480957,2.444552734375,199.99055480957,1489.599875,199.99055480957,,,0.000577033785129249,0.000364098293857659,2.15791864375777e-005,,25,3348.014453125,2444.552734375,1489599.875,
,30985998.188,,1.80005110263824,21493.571953125,5.87874675199031e+022,3.21086954101562,199.99055480957,2.35843100585938,199.99055480957,1489.599875,199.99055480957,,,0.0035873245457584,0.00187839811001723,2.15791864375777e-005,,25,3210.86954101563,2358.43100585938,1489599.875,
,30986968.704,,1.7999210691452,-75548.3734375,5.87874675199031e+022,3.31054161132813,199.99055480957,2.42240461914063,199.99055480957,1489.599875,199.99055480957,,,0.0016076945147342,0.00130180210990176,2.15791864375777e-005,,25,3310.54161132812,2422.40461914063,1489599.875,
,30987940.516,,1.79994701385498,-140000.3925,5.87874675199031e+022,3.349028203125,199.99055480957,2.44637858398438,199.99055480957,1489.599875,199.99055480957,,,0.000249575523470209,0.00026984346875827,2.15791864375777e-005,,25,3349.028203125,2446.37858398437,1489599.875,
,30988898.297,,1.80016338825226,-140000.20875,5.87874675199031e+022,3.348909453125,199.99055480957,2.44635293945313,199.99055480957,1489.599875,199.99055480957,,,0.000217574246254908,0.000306632048578041,2.15791864375777e-005,,25,3348.909453125,2446.35293945313,1489599.875,
,30989863.36,,1.79985545635223,-140000.356875,5.87874675199031e+022,3.348951015625,199.99055480957,2.44628698242188,199.99055480957,1489.599875,199.99055480957,,,0.000310998993458432,0.000375939512511278,2.15791864375777e-005,,25,3348.951015625,2446.28698242188,1489599.875,
,30990835.75,,1.79999197006226,-140000.27,5.87874675199031e+022,3.34881458984375,199.99055480957,2.44631576171875,199.99055480957,1489.599875,199.99055480957,,,0.000288710896044535,0.000248182899333242,2.15791864375777e-005,,25,3348.81458984375,2446.31576171875,1489599.875,
,30991803.532,,1.7999343919754,-140000.17,5.87874675199031e+022,3.3488478515625,199.99055480957,2.44645624023437,199.99055480957,1489.599875,199.99055480957,,,0.000287439754840196,0.000414748119141096,2.15791864375777e-005,,25,3348.8478515625,2446.45624023437,1489599.875,
,30992782.672,,1.79987259864807,-140000.406875,5.87874675199031e+022,3.34887279296875,199.99055480957,2.44631317382813,199.99055480957,1489.599875,199.99055480957,,,0.000321098688428053,0.00028694011222611,2.15791864375777e-005,,25,3348.87279296875,2446.31317382812,1489599.875,
,30993746.594,,1.80010153770447,-140000.363125,5.87874675199031e+022,3.34898223632813,199.99055480957,2.44615545898438,199.99055480957,1489.599875,199.99055480957,,,0.000323192554433064,0.000434766426126868,2.15791864375777e-005,,25,3348.98223632813,2446.15545898437,1489599.875,
,30994709.922,,1.80030134677887,-140000.379375,5.87874675199031e+022,3.34986506835938,199.99055480957,2.44624518554688,199.99055480957,1489.599875,199.99055480957,,,0.000239554159536477,0.00047713369968525,2.15791864375777e-005,,25,3349.86506835938,2446.24518554687,1489599.875,
,30995686.657,,1.80003512382507,-66273.87640625,5.87874675199031e+022,3.29909940429688,199.99055480957,2.41341638671875,199.99055480957,1489.599875,199.99055480957,,,0.00176826531626027,0.00127142635706095,2.15791864375777e-005,,25,3299.09940429688,2413.41638671875,1489599.875,
,30996656.657,,1.80003643989563,-0.0501896689832211,5.87874675199031e+022,3.13407084960938,199.99055480957,2.32171983398438,199.99055480957,1489.599875,199.99055480957,,,0.000385109609039341,0.000621971838566961,2.15791864375777e-005,,25,3134.07084960937,2321.71983398437,1489599.875,
,30997632.891,,1.80009098529816,-0.285135524868965,5.87874675199031e+022,3.13349120117188,199.99055480957,2.3215460546875,199.99055480957,1489.599875,199.99055480957,,,0.00046760236820213,0.000426710662493913,2.15791864375777e-005,,25,3133.49120117188,2321.5460546875,1489599.875,
,30998594.172,,1.79997065544128,-0.369512356519699,5.87874675199031e+022,3.13388594726563,199.99055480957,2.32150244140625,199.99055480957,1489.599875,199.99055480957,,,0.000394266570809346,0.000686939253969593,2.15791864375777e-005,,25,3133.88594726563,2321.50244140625,1489599.875,
,30999559.954,,1.79990175247192,-0.422611560821533,5.87874675199031e+022,3.13369557617188,199.99055480957,2.32169206054688,199.99055480957,1489.599875,199.99055480957,,,0.000295562458430723,0.000733225580754094,2.15791864375777e-005,,25,3133.69557617188,2321.69206054687,1489599.875,
,31000545.344,,1.80006165504456,55291.458125,5.87874675199031e+022,2.92845546875,299.992095947266,2.06884696289062,299.992095947266,1489.599875,299.992095947266,,,0.00299763665460112,0.00140821988681193,2.15791864375777e-005,,25,2928.45546875,2068.84696289063,1489599.875,
,31001513.704,,1.80011106967926,140000.383125,5.87874675199031e+022,3.01810630859375,299.992095947266,2.11909194335937,299.992095947266,1489.599875,299.992095947266,,,0.000409565493471077,0.000415204455974384,2.15791864375777e-005,,25,3018.10630859375,2119.09194335937,1489599.875,
,31002479.766,,1.79999128341675,140000.29625,5.87874675199031e+022,3.01813741210938,299.992095947266,2.11903793945312,299.992095947266,1489.599875,299.992095947266,,,0.000366889993926577,0.000306090562399644,2.15791864375777e-005,,25,3018.13741210938,2119.03793945313,1489599.875,
,31003449.016,,1.80015435695648,140000.305625,5.87874675199031e+022,3.01813109375,299.992095947266,2.11899559570312,299.992095947266,1489.599875,299.992095947266,,,0.000349214414522436,0.000248985870563557,2.15791864375777e-005,,25,3018.13109375,2118.99559570313,1489599.875,
,31004414.688,,1.80013557910919,140000.209375,5.87874675199031e+022,3.01708522460938,299.992095947266,2.11899170898438,299.992095947266,1489.599875,299.992095947266,,,0.000233198916530465,0.000503708745990215,2.15791864375777e-005,,25,3017.08522460938,2118.99170898437,1489599.875,
,31005374.766,,1.80013745307922,106986.8090625,5.87874675199031e+022,3.00077494140625,299.992095947266,2.11136838867187,299.992095947266,1489.599875,299.992095947266,,,0.00106876978352397,0.000719159385814114,2.15791864375777e-005,,25,3000.77494140625,2111.36838867188,1489599.875,
,31006349.125,,1.80026143074036,10274.7388867187,5.87874675199031e+022,2.75341692382813,299.992095947266,1.96800522949219,299.992095947266,1489.599875,299.992095947266,,,0.00874229691216667,0.00609407142184061,2.15791864375777e-005,,25,2753.41692382813,1968.00522949219,1489599.875,
,31007309.391,,1.80003125190735,-85831.5778125,5.87874675199031e+022,2.9728075390625,299.992095947266,2.09948118164063,299.992095947266,1489.599875,299.992095947266,,,0.00203706206590517,0.00104104289406116,2.15791864375777e-005,,25,2972.8075390625,2099.48118164063,1489599.875,
,31008273.11,,1.79999834060669,-140000.346875,5.87874675199031e+022,3.01147754882812,299.992095947266,2.12127629882812,299.992095947266,1489.599875,299.992095947266,,,0.000348875907107244,0.000494831859297953,2.15791864375777e-005,,25,3011.47754882812,2121.27629882813,1489599.875,
,31009237.719,,1.79981127262115,-140000.250625,5.87874675199031e+022,3.01186002929688,299.992095947266,2.12114221679688,299.992095947266,1489.599875,299.992095947266,,,0.000269540227510546,0.00040350523316632,2.15791864375777e-005,,25,3011.86002929687,2121.14221679687,1489599.875,
,31010210.266,,1.79998851776123,-140000.309375,5.87874675199031e+022,3.01195212890625,299.992095947266,2.12105875976562,299.992095947266,0.1754369921875,299.992095947266,,,0.000292069972688777,0.000366815772234505,0.859462225736027,,25,3011.95212890625,2121.05875976562,175.4369921875,
,31011180.454,,1.80030637264252,-140000.36375,5.87874675199031e+022,3.01196333984375,299.992095947266,2.1213162890625,299.992095947266,0,299.992095947266,,,0.000307105099054341,0.000463972464366017,0,,25,3011.96333984375,2121.3162890625,0,
,31012147.875,,1.7999047088623,-140000.316875,5.87874675199031e+022,3.01163626953125,299.992095947266,2.1212169921875,299.992095947266,0,299.992095947266,,,0.000349761673131926,0.000401373715835389,0,,25,3011.63626953125,2121.2169921875,0,
,31013093.36,,1.80008164405823,-140000.285,5.87874675199031e+022,3.01116319335937,299.992095947266,2.1211568359375,299.992095947266,0,299.992095947266,,,0.000413974230832361,0.000373398456489127,0,,25,3011.16319335937,2121.1568359375,0,
,31014059.625,,1.80020644664764,-140000.275625,5.87874675199031e+022,3.01130583984375,299.992095947266,2.12118763671875,299.992095947266,0,299.992095947266,,,0.000365645573913297,0.000384938039734324,0,,25,3011.30583984375,2121.18763671875,0,
,31015038.844,,1.80014398574829,-140000.339375,5.87874675199031e+022,3.0114116796875,299.992095947266,2.1211673046875,299.992095947266,0,299.992095947266,,,0.000348215158108996,0.00048535090718354,0,,25,3011.4116796875,2121.1673046875,0,
,31015997.875,,1.79997487545013,-57634.30625,5.87874675199031e+022,2.92867963867187,299.992095947266,2.07252100585937,299.992095947266,0,299.992095947266,,,0.0025831321881069,0.00137239836358537,0,,25,2928.67963867188,2072.52100585937,0,
,31016969.422,,1.80002000808716,-0.00145477309823036,5.87874675199031e+022,2.69631919921875,299.992095947266,1.925807421875,299.992095947266,0,299.992095947266,,,0.000634170351900696,0.000604660336864313,0,,25,2696.31919921875,1925.807421875,0,
,31017933.188,,1.80000648498535,-0.206577768325806,5.87874675199031e+022,2.69616442382813,299.992095947266,1.92582846191406,299.992095947266,0,299.992095947266,,,0.000414508917612239,0.000911293465434198,0,,25,2696.16442382813,1925.82846191406,0,
,31018900.75,,1.80000295162201,-0.311321440935135,5.87874675199031e+022,2.69608764648437,299.992095947266,1.92585921875,299.992095947266,0,299.992095947266,,,0.000719915461602896,0.000788910685223315,0,,25,2696.08764648438,1925.85921875,0,
,31019867.407,,1.79999769687653,-0.297501092255116,5.87874675199031e+022,2.69599904296875,299.992095947266,1.92566125488281,299.992095947266,0.334325,299.992095947266,,,0.000455347363586664,0.000803164919328259,1.63785131651197,,25,2695.99904296875,1925.66125488281,334.325,
,31020834.219,,1.80011564254761,-0.218215959668159,5.87874675199031e+022,2.69628419921875,299.992095947266,1.92569491699219,299.992095947266,0,299.992095947266,,,0.000666451225098452,0.000847101354929052,0,,25,2696.28419921875,1925.69491699219,0,
,31021794.063,,1.80011490345001,-0.157115489542484,5.87874675199031e+022,2.696231328125,299.992095947266,1.92571979492187,299.992095947266,0,299.992095947266,,,0.000381941582682094,0.000797469839715842,0,,25,2696.231328125,1925.71979492188,0,
,31022772.875,,1.80011473178864,-0.121473550349474,5.87874675199031e+022,2.69630663085938,299.992095947266,1.92579458984375,299.992095947266,0,299.992095947266,,,0.000408762054979015,0.000535136533090751,0,,25,2696.30663085938,1925.79458984375,0,
,31023747.875,,1.80010121822357,-0.0596456949412823,5.87874675199031e+022,2.69618106445313,299.992095947266,1.92566807128906,299.992095947266,0,299.992095947266,,,0.00057707303605742,0.000987770499385926,0,,25,2696.18106445313,1925.66807128906,0,
,31024721.813,,1.80008017063141,-0.0756481963396072,5.87874675199031e+022,2.69633751953125,299.992095947266,1.92589529296875,299.992095947266,0,299.992095947266,,,0.000627830954023528,0.000762685500311449,0,,25,2696.33751953125,1925.89529296875,0,
,31025699.266,,1.80008903503418,33756.57203125,5.87874675199031e+022,2.48380375976562,399.993621826172,1.69439140136719,399.993621826172,0,399.993621826172,,,0.00599138317548497,0.0044449462213811,0,,25,2483.80375976562,1694.39140136719,0,
,31026662.719,,1.79999698638916,130449.3434375,5.87874675199031e+022,2.68824418945313,399.993621826172,1.83605364257813,399.993621826172,0,399.993621826172,,,0.00113919625451982,0.0008828111247192,0,,25,2688.24418945312,1836.05364257812,0,
,31027629.25,,1.80005327701569,139999.980625,5.87874675199031e+022,2.69545546875,399.993621826172,1.84007046875,399.993621826172,0,399.993621826172,,,0.000397288041819533,0.000584962589321471,0,,25,2695.45546875,1840.07046875,0,
,31028588.407,,1.80011918067932,140000.111875,5.87874675199031e+022,2.69373909179688,399.993621826172,1.83982854980469,399.993621826172,0,399.993621826172,,,0.000803508902111886,0.000507680123973834,0,,25,2693.73909179688,1839.82854980469,0,
,31029550.922,,1.80008434295654,140000.136875,5.87874675199031e+022,2.69356840820313,399.993621826172,1.84001842285156,399.993621826172,0,399.993621826172,,,0.000733684372745914,0.000380646997244208,0,,25,2693.56840820312,1840.01842285156,0,
,31030528.032,,1.7999355173111,126917.7284375,5.87874675199031e+022,2.68502127929687,399.993621826172,1.83408658203125,399.993621826172,0,399.993621826172,,,0.00109353425306423,0.000878834277251853,0,,25,2685.02127929688,1834.08658203125,0,
,31031496.641,,1.80009599208832,30861.486328125,5.87874675199031e+022,2.47105583007813,399.993621826172,1.68548609375,399.993621826172,0,399.993621826172,,,0.00637528429640158,0.00433349947947721,0,,25,2471.05583007812,1685.48609375,0,
,31032474.563,,1.8000021314621,-66891.65265625,5.87874675199031e+022,2.60378854492187,399.993621826172,1.7793814453125,399.993621826172,0,399.993621826172,,,0.00273321564428695,0.00205238240539464,0,,25,2603.78854492188,1779.3814453125,0,
,31033439.61,,1.80028961658478,-140000.395,5.87874675199031e+022,2.69565354492188,399.993621826172,1.84576829589844,399.993621826172,0,399.993621826172,,,0.000582289623622588,0.000326988128697628,0,,25,2695.65354492188,1845.76829589844,0,
,31034403.954,,1.80003095626831,-140000.428125,5.87874675199031e+022,2.69573087890625,399.993621826172,1.84601471679687,399.993621826172,0,399.993621826172,,,0.000556334707692887,0.000609771514562206,0,,25,2695.73087890625,1846.01471679688,0,
,31035376.625,,1.80014241695404,-140000.37625,5.87874675199031e+022,2.69577809570312,399.993621826172,1.84579310058594,399.993621826172,0,399.993621826172,,,0.000552968476306968,0.000396181677956768,0,,25,2695.77809570313,1845.79310058594,0,
,31036356.86,,1.8001554441452,-140000.405,5.87874675199031e+022,2.69587673828125,399.993621826172,1.84582936523438,399.993621826172,0,399.993621826172,,,0.000562704373859647,0.00041069009726678,0,,25,2695.87673828125,1845.82936523438,0,
,31037334.797,,1.80005599498749,-140000.215,5.87874675199031e+022,2.69561034179687,399.993621826172,1.84591944335938,399.993621826172,0,399.993621826172,,,0.000562812658176349,0.000608588227757562,0,,25,2695.61034179688,1845.91944335938,0,
,31038310.563,,1.79996336936951,-140000.1325,5.87874675199031e+022,2.6955426953125,399.993621826172,1.84569581054687,399.993621826172,0,399.993621826172,,,0.000520843778544082,0.000337336909111128,0,,25,2695.5426953125,1845.69581054688,0,
,31039285.563,,1.80000144481659,-140000.1475,5.87874675199031e+022,2.69574048828125,399.993621826172,1.84600444335938,399.993621826172,0,399.993621826172,,,0.000518870290226887,0.000562404069024598,0,,25,2695.74048828125,1846.00444335938,0,
,31040254.985,,1.80036697387695,-139999.9425,5.87874675199031e+022,2.6958459375,399.993621826172,1.84583003417969,399.993621826172,0,399.993621826172,,,0.000521068169956362,0.00049971914153169,0,,25,2695.8459375,1845.83003417969,0,
,31041223.407,,1.80020738124847,-77030.746875,5.87874675199031e+022,2.62365612304688,399.993621826172,1.79474131835938,399.993621826172,0,399.993621826172,,,0.00238927720168638,0.00206095162652634,0,,25,2623.65612304688,1794.74131835938,0,
,31042192.844,,1.80006279945374,-0.128020029067993,5.87874675199031e+022,2.23772400390625,399.993621826172,1.50191903808594,399.993621826172,0,399.993621826172,,,0.00115985942742881,0.00137040074044182,0,,25,2237.72400390625,1501.91903808594,0,
,31043155.11,,1.800170545578,-0.260404378771782,5.87874675199031e+022,2.23744350585937,399.993621826172,1.50188547363281,399.993621826172,0,399.993621826172,,,0.00126406713735133,0.00126104357888384,0,,25,2237.44350585937,1501.88547363281,0,
,31044123.516,,1.80006942272186,-0.325141781568527,5.87874675199031e+022,2.23754676757813,399.993621826172,1.50181571289062,399.993621826172,0,399.993621826172,,,0.000996910561008992,0.00114369236087261,0,,25,2237.54676757813,1501.81571289063,0,
,31045089.938,,1.80004313468933,-0.371694515943527,5.87874675199031e+022,2.2372400390625,399.993621826172,1.5018501953125,399.993621826172,0,399.993621826172,,,0.000840859275306509,0.00130838965953437,0,,25,2237.2400390625,1501.8501953125,0,
,31046072.797,,1.80012373447418,44019.81171875,5.87874675199031e+022,2.07610841796875,499.995147705078,1.35852336914063,499.995147705078,0,499.995147705078,,,0.00597055671672436,0.00475870327345707,0,,25,2076.10841796875,1358.52336914062,0,
,31047047.157,,1.79998833656311,139978.59,5.87874675199031e+022,2.31824987304687,499.995147705078,1.55506854003906,499.995147705078,0,499.995147705078,,,0.000655424893845469,0.000865795750754265,0,,25,2318.24987304688,1555.06854003906,0,
,31048020.188,,1.79995140552521,140000.37625,5.87874675199031e+022,2.31791639648438,499.995147705078,1.55506321289063,499.995147705078,0,499.995147705078,,,0.000944648115590074,0.000771607062205571,0,,25,2317.91639648438,1555.06321289063,0,
,31048982.204,,1.80018346786499,140000.1025,5.87874675199031e+022,2.31662524414063,499.995147705078,1.55523878417969,499.995147705078,0,499.995147705078,,,0.000826116360466933,0.000659004361734416,0,,25,2316.62524414063,1555.23878417969,0,
,31049954.704,,1.80028887748718,140000.1425,5.87874675199031e+022,2.31741209960938,499.995147705078,1.55522612792969,499.995147705078,0,499.995147705078,,,0.000941605570006545,0.000425335616509162,0,,25,2317.41209960938,1555.22612792969,0,
,31050924.25,,1.800061211586,116786.775,5.87874675199031e+022,2.28073870117188,499.995147705078,1.52745053222656,499.995147705078,0,499.995147705078,,,0.00265231494848704,0.00241479409819078,0,,25,2280.73870117188,1527.45053222656,0,
,31051896.329,,1.80024837493896,20368.515703125,5.87874675199031e+022,1.93736185546875,499.995147705078,1.25166958007813,499.995147705078,0,499.995147705078,,,0.010312810056711,0.00762613479684432,0,,25,1937.36185546875,1251.66958007812,0,
,31052873.547,,1.79987388134003,-77307.05875,5.87874675199031e+022,2.25587961914063,499.995147705078,1.47049699707031,499.995147705078,0,499.995147705078,,,0.00283414067434866,0.00282357276031367,0,,25,2255.87961914063,1470.49699707031,0,
,31053848.079,,1.80025761127472,-140000.288125,5.87874675199031e+022,2.35284700195312,499.995147705078,1.56714029785156,499.995147705078,0,499.995147705078,,,0.00121810192718921,0.000963415229483952,0,,25,2352.84700195313,1567.14029785156,0,
,31054828.094,,1.80010759353638,-140000.3,5.87874675199031e+022,2.35172993164063,499.995147705078,1.56698774902344,499.995147705078,0,499.995147705078,,,0.000630364311432205,0.000896514725459538,0,,25,2351.72993164063,1566.98774902344,0,
,31055794.172,,1.79998039245605,-140000.385625,5.87874675199031e+022,2.35218647460938,499.995147705078,1.56699743652344,499.995147705078,0,499.995147705078,,,0.000576409567936891,0.000832524525465982,0,,25,2352.18647460938,1566.99743652344,0,
,31056768.704,,1.80033330440521,-140000.195625,5.87874675199031e+022,2.352337421875,499.995147705078,1.56707316894531,499.995147705078,0,499.995147705078,,,0.000639659839378267,0.00080470679717542,0,,25,2352.337421875,1567.07316894531,0,
,31057725.922,,1.80019267559052,-140000.28125,5.87874675199031e+022,2.3523214453125,499.995147705078,1.56675234375,499.995147705078,0,499.995147705078,,,0.000578109793719712,0.000592132629450278,0,,25,2352.3214453125,1566.75234375,0,
,31058705.047,,1.79985691547394,-140000.141875,5.87874675199031e+022,2.352160078125,499.995147705078,1.56705548339844,499.995147705078,0,499.995147705078,,,0.000762984036562305,0.000978106005570874,0,,25,2352.160078125,1567.05548339844,0,
,31059671.25,,1.80022730827332,-140000.104375,5.87874675199031e+022,2.35207876953125,499.995147705078,1.566837421875,499.995147705078,0,499.995147705078,,,0.000996462859470547,0.00105388519187901,0,,25,2352.07876953125,1566.837421875,0,
,31060641.407,,1.80007281780243,-140000.224375,5.87874675199031e+022,2.35222958007813,499.995147705078,1.56710963378906,499.995147705078,0,499.995147705078,,,0.000690476020658116,0.00084253418323749,0,,25,2352.22958007812,1567.10963378906,0,
,31061610.313,,1.80011966228485,-66442.1209375,5.87874675199031e+022,2.22884638671875,499.995147705078,1.44584478027344,499.995147705078,0,499.995147705078,,,0.0034046191394752,0.00363162961093042,0,,25,2228.84638671875,1445.84478027344,0,
,31062577.219,,1.80015636444092,-0.0414610325545073,5.87874675199031e+022,1.76898302246094,499.995147705078,1.12582499511719,499.995147705078,0,499.995147705078,,,0.000782239207314838,0.00101479281253827,0,,25,1768.98302246094,1125.82499511719,0,
,31063547.407,,1.80016933917999,-0.239310165643692,5.87874675199031e+022,1.76836350097656,499.995147705078,1.12551469726562,499.995147705078,0,499.995147705078,,,0.00135027983084669,0.00076283160562427,0,,25,1768.36350097656,1125.51469726563,0,
,31064511.594,,1.79996341705322,-0.357874175310135,5.87874675199031e+022,1.76844799316406,499.995147705078,1.12599351074219,499.995147705078,0,499.995147705078,,,0.00148097703145232,0.0011597780030065,0,,25,1768.44799316406,1125.99351074219,0,
,31065482.657,,1.80008463382721,-0.3556920170784,5.87874675199031e+022,1.76866920898437,499.995147705078,1.12592903808594,499.995147705078,0,499.995147705078,,,0.00130788822302174,0.0014140632374417,0,,25,1768.66920898438,1125.92903808594,0,
,31066468.813,,1.80044602394104,54993.50109375,5.87874675199031e+022,1.17780305175781,749.998962402344,0.765761389160156,749.998962402344,0,749.998962402344,,,0.00473936610189543,0.00293298264442001,0,,25,1177.80305175781,765.761389160156,0,
,31067439.782,,1.80019538879395,140000.334375,5.87874675199031e+022,1.4089416796875,749.998962402344,0.945523435058594,749.998962402344,0,749.998962402344,,,0.00122008519177497,0.0010319599620163,0,,25,1408.9416796875,945.523435058594,0,
,31068404.032,,1.80003240585327,140000.236875,5.87874675199031e+022,1.40918806152344,749.998962402344,0.945631042480469,749.998962402344,0,749.998962402344,,,0.00104716486108623,0.00112393185870469,0,,25,1409.18806152344,945.631042480469,0,
,31069367.907,,1.80007224082947,140000.36875,5.87874675199031e+022,1.40863913574219,749.998962402344,0.945056613769531,749.998962402344,0,749.998962402344,,,0.0015954737026791,0.00131291859271963,0,,25,1408.63913574219,945.056613769531,0,
,31070346.563,,1.80016091823578,140000.178125,5.87874675199031e+022,1.40908802246094,749.998962402344,0.944967456054687,749.998962402344,0,749.998962402344,,,0.000743843489792901,0.000866314489765069,0,,25,1409.08802246094,944.967456054688,0,
,31071317.782,,1.80019899368286,106937.205,5.87874675199031e+022,1.33246840332031,749.998962402344,0.8875151953125,749.998962402344,0,749.998962402344,,,0.00341687599462301,0.00312572082157,0,,25,1332.46840332031,887.5151953125,0,
,31072280.266,,1.80036017894745,11349.2582421875,5.87874675199031e+022,1.00003709960938,749.998962402344,0.613298752441406,749.998962402344,0,749.998962402344,,,0.00495796884483368,0.00584015966421382,0,,25,1000.03709960938,613.298752441406,0,
,31073246.407,,1.79989172935486,-85282.7584375,5.87874675199031e+022,1.49075291015625,749.998962402344,0.845242556152344,749.998962402344,0,749.998962402344,,,0.00322509377442756,0.00250145207028881,0,,25,1490.75291015625,845.242556152344,0,
,31074218.157,,1.80051813602448,-140000.338125,5.87874675199031e+022,1.61071379882813,749.998962402344,0.95320931640625,749.998962402344,0,749.998962402344,,,0.000977679232573627,0.0011985890055163,0,,25,1610.71379882812,953.20931640625,0,
,31075178.329,,1.79995489120483,-140000.188125,5.87874675199031e+022,1.61031493652344,749.998962402344,0.95285810546875,749.998962402344,0,749.998962402344,,,0.000881505828109898,0.000903575678108448,0,,25,1610.31493652344,952.85810546875,0,
,31076149.829,,1.79973035335541,-140000.188125,5.87874675199031e+022,1.61008045898437,749.998962402344,0.952590783691406,749.998962402344,0,749.998962402344,,,0.00146122956421516,0.00146861351264522,0,,25,1610.08045898437,952.590783691406,0,
,31077119.172,,1.80019261837006,-140000.25,5.87874675199031e+022,1.61086430175781,749.998962402344,0.952914697265625,749.998962402344,0,749.998962402344,,,0.000696309760005263,0.00114128319082826,0,,25,1610.86430175781,952.914697265625,0,
,31078091.563,,1.80056175708771,-140000.234375,5.87874675199031e+022,1.61040290039063,749.998962402344,0.952962646484375,749.998962402344,0,749.998962402344,,,0.000653602927498123,0.000895926653143713,0,,25,1610.40290039063,952.962646484375,0,
,31079062.61,,1.80045958518982,-140000.224375,5.87874675199031e+022,1.61004933105469,749.998962402344,0.952824204101562,749.998962402344,0,749.998962402344,,,0.000791576051791212,0.000718793927518352,0,,25,1610.04933105469,952.824204101562,0,
,31080035.547,,1.80013971328735,-140000.201875,5.87874675199031e+022,1.60984844726563,749.998962402344,0.9528682421875,749.998962402344,0,749.998962402344,,,0.00119738457248548,0.00124609063816355,0,,25,1609.84844726563,952.8682421875,0,
,31081003.5,,1.800371966362,-140000.170625,5.87874675199031e+022,1.60998375976563,749.998962402344,0.952848469238281,749.998962402344,0,749.998962402344,,,0.00085935427153605,0.000679566680881412,0,,25,1609.98375976563,952.848469238281,0,
,31081971.047,,1.80031802654266,-56482.95671875,5.87874675199031e+022,1.39771014648438,749.998962402344,0.775127958984375,749.998962402344,0,749.998962402344,,,0.00474843704810288,0.00350956774443464,0,,25,1397.71014648437,775.127958984375,0,
,31082644.75,,1.80018504142761,-0.232036297917366,5.87874675199031e+022,1.00429755371094,749.998962402344,0.581721091308594,749.998962402344,0,749.998962402344,,,0.00157624899581198,0.00147724981481518,0,,25,1004.29755371094,581.721091308594,0,